{
 "cells": [
  {
   "cell_type": "code",
   "execution_count": 1,
   "metadata": {},
   "outputs": [],
   "source": [
    "import cv2\n",
    "import os\n",
    "import tensorflow as tf\n",
    "import numpy as np\n",
    "import opendatasets as od\n",
    "\n",
    "from tensorflow import keras"
   ]
  },
  {
   "cell_type": "code",
   "execution_count": 2,
   "metadata": {},
   "outputs": [
    {
     "name": "stdout",
     "output_type": "stream",
     "text": [
      "/teamspace/studios/this_studio\n"
     ]
    }
   ],
   "source": [
    "print(os.getcwd())\n",
    "if 'Emotions' not in os.getcwd():\n",
    "    os.chdir(os.getcwd() + '/Emotions-ImageClassification-TensorFlow')"
   ]
  },
  {
   "cell_type": "code",
   "execution_count": 3,
   "metadata": {},
   "outputs": [
    {
     "data": {
      "text/plain": [
       "'/teamspace/studios/this_studio/Emotions-ImageClassification-TensorFlow'"
      ]
     },
     "execution_count": 3,
     "metadata": {},
     "output_type": "execute_result"
    }
   ],
   "source": [
    "os.getcwd()"
   ]
  },
  {
   "cell_type": "code",
   "execution_count": 4,
   "metadata": {},
   "outputs": [],
   "source": [
    "train = tf.data.Dataset.load('data_compressed/train')\n",
    "test = tf.data.Dataset.load('data_compressed/test')\n",
    "val = tf.data.Dataset.load('data_compressed/val')"
   ]
  },
  {
   "cell_type": "code",
   "execution_count": 5,
   "metadata": {},
   "outputs": [
    {
     "name": "stdout",
     "output_type": "stream",
     "text": [
      "28272\n",
      "3534\n",
      "3534\n"
     ]
    },
    {
     "data": {
      "text/plain": [
       "[None, None, None]"
      ]
     },
     "execution_count": 5,
     "metadata": {},
     "output_type": "execute_result"
    }
   ],
   "source": [
    "[print(len(i)) for i in [train, test, val]]"
   ]
  },
  {
   "cell_type": "code",
   "execution_count": 6,
   "metadata": {},
   "outputs": [
    {
     "name": "stdout",
     "output_type": "stream",
     "text": [
      "<_LoadDataset element_spec=(TensorSpec(shape=(32, 32, 1), dtype=tf.float32, name=None), TensorSpec(shape=(6,), dtype=tf.float32, name=None))>\n"
     ]
    }
   ],
   "source": [
    "print(train)"
   ]
  },
  {
   "cell_type": "code",
   "execution_count": 10,
   "metadata": {},
   "outputs": [],
   "source": [
    "train = train.batch(batch_size=32).cache().prefetch(tf.data.AUTOTUNE)\n",
    "test = test.batch(batch_size=32).cache().prefetch(tf.data.AUTOTUNE)\n",
    "val = val.batch(batch_size=32).cache().prefetch(tf.data.AUTOTUNE)"
   ]
  },
  {
   "cell_type": "code",
   "execution_count": 11,
   "metadata": {},
   "outputs": [
    {
     "name": "stdout",
     "output_type": "stream",
     "text": [
      "<_PrefetchDataset element_spec=(TensorSpec(shape=(None, 32, 32, 1), dtype=tf.float32, name=None), TensorSpec(shape=(None, 6), dtype=tf.float32, name=None))>\n"
     ]
    }
   ],
   "source": [
    "print(train)"
   ]
  },
  {
   "cell_type": "code",
   "execution_count": 12,
   "metadata": {},
   "outputs": [
    {
     "name": "stderr",
     "output_type": "stream",
     "text": [
      "2024-05-08 07:23:23.617004: W tensorflow/core/framework/local_rendezvous.cc:404] Local rendezvous is aborting with status: DATA_LOSS: corrupted record at 0 (Is this even a TFRecord file?)\n",
      "\t [[{{node IteratorGetNext}}]]\n"
     ]
    },
    {
     "ename": "DataLossError",
     "evalue": "Graph execution error:\n\nDetected at node IteratorGetNext defined at (most recent call last):\n  File \"/home/zeus/miniconda3/envs/cloudspace/lib/python3.10/runpy.py\", line 196, in _run_module_as_main\n\n  File \"/home/zeus/miniconda3/envs/cloudspace/lib/python3.10/runpy.py\", line 86, in _run_code\n\n  File \"/home/zeus/miniconda3/envs/cloudspace/lib/python3.10/site-packages/ipykernel_launcher.py\", line 17, in <module>\n\n  File \"/home/zeus/miniconda3/envs/cloudspace/lib/python3.10/site-packages/traitlets/config/application.py\", line 1075, in launch_instance\n\n  File \"/home/zeus/miniconda3/envs/cloudspace/lib/python3.10/site-packages/ipykernel/kernelapp.py\", line 737, in start\n\n  File \"/home/zeus/miniconda3/envs/cloudspace/lib/python3.10/site-packages/tornado/platform/asyncio.py\", line 205, in start\n\n  File \"/home/zeus/miniconda3/envs/cloudspace/lib/python3.10/asyncio/base_events.py\", line 603, in run_forever\n\n  File \"/home/zeus/miniconda3/envs/cloudspace/lib/python3.10/asyncio/base_events.py\", line 1909, in _run_once\n\n  File \"/home/zeus/miniconda3/envs/cloudspace/lib/python3.10/asyncio/events.py\", line 80, in _run\n\n  File \"/home/zeus/miniconda3/envs/cloudspace/lib/python3.10/site-packages/ipykernel/kernelbase.py\", line 524, in dispatch_queue\n\n  File \"/home/zeus/miniconda3/envs/cloudspace/lib/python3.10/site-packages/ipykernel/kernelbase.py\", line 513, in process_one\n\n  File \"/home/zeus/miniconda3/envs/cloudspace/lib/python3.10/site-packages/ipykernel/kernelbase.py\", line 418, in dispatch_shell\n\n  File \"/home/zeus/miniconda3/envs/cloudspace/lib/python3.10/site-packages/ipykernel/kernelbase.py\", line 758, in execute_request\n\n  File \"/home/zeus/miniconda3/envs/cloudspace/lib/python3.10/site-packages/ipykernel/ipkernel.py\", line 426, in do_execute\n\n  File \"/home/zeus/miniconda3/envs/cloudspace/lib/python3.10/site-packages/ipykernel/zmqshell.py\", line 549, in run_cell\n\n  File \"/home/zeus/miniconda3/envs/cloudspace/lib/python3.10/site-packages/IPython/core/interactiveshell.py\", line 3046, in run_cell\n\n  File \"/home/zeus/miniconda3/envs/cloudspace/lib/python3.10/site-packages/IPython/core/interactiveshell.py\", line 3101, in _run_cell\n\n  File \"/home/zeus/miniconda3/envs/cloudspace/lib/python3.10/site-packages/IPython/core/async_helpers.py\", line 129, in _pseudo_sync_runner\n\n  File \"/home/zeus/miniconda3/envs/cloudspace/lib/python3.10/site-packages/IPython/core/interactiveshell.py\", line 3306, in run_cell_async\n\n  File \"/home/zeus/miniconda3/envs/cloudspace/lib/python3.10/site-packages/IPython/core/interactiveshell.py\", line 3488, in run_ast_nodes\n\n  File \"/home/zeus/miniconda3/envs/cloudspace/lib/python3.10/site-packages/IPython/core/interactiveshell.py\", line 3548, in run_code\n\n  File \"/tmp/ipykernel_112700/1859430353.py\", line 15, in <module>\n\n  File \"/home/zeus/miniconda3/envs/cloudspace/lib/python3.10/site-packages/keras/src/utils/traceback_utils.py\", line 117, in error_handler\n\n  File \"/home/zeus/miniconda3/envs/cloudspace/lib/python3.10/site-packages/keras/src/backend/tensorflow/trainer.py\", line 314, in fit\n\n  File \"/home/zeus/miniconda3/envs/cloudspace/lib/python3.10/site-packages/keras/src/backend/tensorflow/trainer.py\", line 116, in one_step_on_iterator\n\ncorrupted record at 0 (Is this even a TFRecord file?)\n\t [[{{node IteratorGetNext}}]] [Op:__inference_one_step_on_iterator_1494]",
     "output_type": "error",
     "traceback": [
      "\u001b[0;31m---------------------------------------------------------------------------\u001b[0m",
      "\u001b[0;31mDataLossError\u001b[0m                             Traceback (most recent call last)",
      "Cell \u001b[0;32mIn[12], line 15\u001b[0m\n\u001b[1;32m      1\u001b[0m model \u001b[38;5;241m=\u001b[39m keras\u001b[38;5;241m.\u001b[39mSequential([\n\u001b[1;32m      2\u001b[0m     keras\u001b[38;5;241m.\u001b[39mlayers\u001b[38;5;241m.\u001b[39mInput(shape\u001b[38;5;241m=\u001b[39m(\u001b[38;5;241m32\u001b[39m, \u001b[38;5;241m32\u001b[39m, \u001b[38;5;241m1\u001b[39m)),\n\u001b[1;32m      3\u001b[0m     keras\u001b[38;5;241m.\u001b[39mlayers\u001b[38;5;241m.\u001b[39mConv2D(\u001b[38;5;241m32\u001b[39m, kernel_size\u001b[38;5;241m=\u001b[39m\u001b[38;5;241m3\u001b[39m, activation\u001b[38;5;241m=\u001b[39m\u001b[38;5;124m'\u001b[39m\u001b[38;5;124mrelu\u001b[39m\u001b[38;5;124m'\u001b[39m),\n\u001b[0;32m   (...)\u001b[0m\n\u001b[1;32m      7\u001b[0m     keras\u001b[38;5;241m.\u001b[39mlayers\u001b[38;5;241m.\u001b[39mDense(\u001b[38;5;241m6\u001b[39m, activation\u001b[38;5;241m=\u001b[39m\u001b[38;5;124m'\u001b[39m\u001b[38;5;124msoftmax\u001b[39m\u001b[38;5;124m'\u001b[39m)\n\u001b[1;32m      8\u001b[0m ])\n\u001b[1;32m     10\u001b[0m model\u001b[38;5;241m.\u001b[39mcompile(optimizer\u001b[38;5;241m=\u001b[39m\u001b[38;5;124m'\u001b[39m\u001b[38;5;124madam\u001b[39m\u001b[38;5;124m'\u001b[39m, \n\u001b[1;32m     11\u001b[0m               loss\u001b[38;5;241m=\u001b[39mkeras\u001b[38;5;241m.\u001b[39mlosses\u001b[38;5;241m.\u001b[39mCategoricalCrossentropy(),\n\u001b[1;32m     12\u001b[0m               metrics\u001b[38;5;241m=\u001b[39m[\u001b[38;5;124m'\u001b[39m\u001b[38;5;124maccuracy\u001b[39m\u001b[38;5;124m'\u001b[39m])\n\u001b[0;32m---> 15\u001b[0m \u001b[43mmodel\u001b[49m\u001b[38;5;241;43m.\u001b[39;49m\u001b[43mfit\u001b[49m\u001b[43m(\u001b[49m\u001b[43mtrain\u001b[49m\u001b[43m,\u001b[49m\u001b[43m \u001b[49m\u001b[43mepochs\u001b[49m\u001b[38;5;241;43m=\u001b[39;49m\u001b[38;5;241;43m1\u001b[39;49m\u001b[43m,\u001b[49m\u001b[43m \u001b[49m\u001b[43mvalidation_data\u001b[49m\u001b[38;5;241;43m=\u001b[39;49m\u001b[43mval\u001b[49m\u001b[43m)\u001b[49m\n",
      "File \u001b[0;32m/home/zeus/miniconda3/envs/cloudspace/lib/python3.10/site-packages/keras/src/utils/traceback_utils.py:122\u001b[0m, in \u001b[0;36mfilter_traceback.<locals>.error_handler\u001b[0;34m(*args, **kwargs)\u001b[0m\n\u001b[1;32m    119\u001b[0m     filtered_tb \u001b[38;5;241m=\u001b[39m _process_traceback_frames(e\u001b[38;5;241m.\u001b[39m__traceback__)\n\u001b[1;32m    120\u001b[0m     \u001b[38;5;66;03m# To get the full stack trace, call:\u001b[39;00m\n\u001b[1;32m    121\u001b[0m     \u001b[38;5;66;03m# `keras.config.disable_traceback_filtering()`\u001b[39;00m\n\u001b[0;32m--> 122\u001b[0m     \u001b[38;5;28;01mraise\u001b[39;00m e\u001b[38;5;241m.\u001b[39mwith_traceback(filtered_tb) \u001b[38;5;28;01mfrom\u001b[39;00m \u001b[38;5;28;01mNone\u001b[39;00m\n\u001b[1;32m    123\u001b[0m \u001b[38;5;28;01mfinally\u001b[39;00m:\n\u001b[1;32m    124\u001b[0m     \u001b[38;5;28;01mdel\u001b[39;00m filtered_tb\n",
      "File \u001b[0;32m/home/zeus/miniconda3/envs/cloudspace/lib/python3.10/site-packages/tensorflow/python/eager/execute.py:53\u001b[0m, in \u001b[0;36mquick_execute\u001b[0;34m(op_name, num_outputs, inputs, attrs, ctx, name)\u001b[0m\n\u001b[1;32m     51\u001b[0m \u001b[38;5;28;01mtry\u001b[39;00m:\n\u001b[1;32m     52\u001b[0m   ctx\u001b[38;5;241m.\u001b[39mensure_initialized()\n\u001b[0;32m---> 53\u001b[0m   tensors \u001b[38;5;241m=\u001b[39m pywrap_tfe\u001b[38;5;241m.\u001b[39mTFE_Py_Execute(ctx\u001b[38;5;241m.\u001b[39m_handle, device_name, op_name,\n\u001b[1;32m     54\u001b[0m                                       inputs, attrs, num_outputs)\n\u001b[1;32m     55\u001b[0m \u001b[38;5;28;01mexcept\u001b[39;00m core\u001b[38;5;241m.\u001b[39m_NotOkStatusException \u001b[38;5;28;01mas\u001b[39;00m e:\n\u001b[1;32m     56\u001b[0m   \u001b[38;5;28;01mif\u001b[39;00m name \u001b[38;5;129;01mis\u001b[39;00m \u001b[38;5;129;01mnot\u001b[39;00m \u001b[38;5;28;01mNone\u001b[39;00m:\n",
      "\u001b[0;31mDataLossError\u001b[0m: Graph execution error:\n\nDetected at node IteratorGetNext defined at (most recent call last):\n  File \"/home/zeus/miniconda3/envs/cloudspace/lib/python3.10/runpy.py\", line 196, in _run_module_as_main\n\n  File \"/home/zeus/miniconda3/envs/cloudspace/lib/python3.10/runpy.py\", line 86, in _run_code\n\n  File \"/home/zeus/miniconda3/envs/cloudspace/lib/python3.10/site-packages/ipykernel_launcher.py\", line 17, in <module>\n\n  File \"/home/zeus/miniconda3/envs/cloudspace/lib/python3.10/site-packages/traitlets/config/application.py\", line 1075, in launch_instance\n\n  File \"/home/zeus/miniconda3/envs/cloudspace/lib/python3.10/site-packages/ipykernel/kernelapp.py\", line 737, in start\n\n  File \"/home/zeus/miniconda3/envs/cloudspace/lib/python3.10/site-packages/tornado/platform/asyncio.py\", line 205, in start\n\n  File \"/home/zeus/miniconda3/envs/cloudspace/lib/python3.10/asyncio/base_events.py\", line 603, in run_forever\n\n  File \"/home/zeus/miniconda3/envs/cloudspace/lib/python3.10/asyncio/base_events.py\", line 1909, in _run_once\n\n  File \"/home/zeus/miniconda3/envs/cloudspace/lib/python3.10/asyncio/events.py\", line 80, in _run\n\n  File \"/home/zeus/miniconda3/envs/cloudspace/lib/python3.10/site-packages/ipykernel/kernelbase.py\", line 524, in dispatch_queue\n\n  File \"/home/zeus/miniconda3/envs/cloudspace/lib/python3.10/site-packages/ipykernel/kernelbase.py\", line 513, in process_one\n\n  File \"/home/zeus/miniconda3/envs/cloudspace/lib/python3.10/site-packages/ipykernel/kernelbase.py\", line 418, in dispatch_shell\n\n  File \"/home/zeus/miniconda3/envs/cloudspace/lib/python3.10/site-packages/ipykernel/kernelbase.py\", line 758, in execute_request\n\n  File \"/home/zeus/miniconda3/envs/cloudspace/lib/python3.10/site-packages/ipykernel/ipkernel.py\", line 426, in do_execute\n\n  File \"/home/zeus/miniconda3/envs/cloudspace/lib/python3.10/site-packages/ipykernel/zmqshell.py\", line 549, in run_cell\n\n  File \"/home/zeus/miniconda3/envs/cloudspace/lib/python3.10/site-packages/IPython/core/interactiveshell.py\", line 3046, in run_cell\n\n  File \"/home/zeus/miniconda3/envs/cloudspace/lib/python3.10/site-packages/IPython/core/interactiveshell.py\", line 3101, in _run_cell\n\n  File \"/home/zeus/miniconda3/envs/cloudspace/lib/python3.10/site-packages/IPython/core/async_helpers.py\", line 129, in _pseudo_sync_runner\n\n  File \"/home/zeus/miniconda3/envs/cloudspace/lib/python3.10/site-packages/IPython/core/interactiveshell.py\", line 3306, in run_cell_async\n\n  File \"/home/zeus/miniconda3/envs/cloudspace/lib/python3.10/site-packages/IPython/core/interactiveshell.py\", line 3488, in run_ast_nodes\n\n  File \"/home/zeus/miniconda3/envs/cloudspace/lib/python3.10/site-packages/IPython/core/interactiveshell.py\", line 3548, in run_code\n\n  File \"/tmp/ipykernel_112700/1859430353.py\", line 15, in <module>\n\n  File \"/home/zeus/miniconda3/envs/cloudspace/lib/python3.10/site-packages/keras/src/utils/traceback_utils.py\", line 117, in error_handler\n\n  File \"/home/zeus/miniconda3/envs/cloudspace/lib/python3.10/site-packages/keras/src/backend/tensorflow/trainer.py\", line 314, in fit\n\n  File \"/home/zeus/miniconda3/envs/cloudspace/lib/python3.10/site-packages/keras/src/backend/tensorflow/trainer.py\", line 116, in one_step_on_iterator\n\ncorrupted record at 0 (Is this even a TFRecord file?)\n\t [[{{node IteratorGetNext}}]] [Op:__inference_one_step_on_iterator_1494]"
     ]
    }
   ],
   "source": [
    "model = keras.Sequential([\n",
    "    keras.layers.Input(shape=(32, 32, 1)),\n",
    "    keras.layers.Conv2D(32, kernel_size=3, activation='relu'),\n",
    "    keras.layers.MaxPooling2D(),\n",
    "    keras.layers.Flatten(),\n",
    "    keras.layers.Dense(128, activation='relu'),\n",
    "    keras.layers.Dense(6, activation='softmax')\n",
    "])\n",
    "\n",
    "model.compile(optimizer='adam', \n",
    "              loss=keras.losses.CategoricalCrossentropy(),\n",
    "              metrics=['accuracy'])\n",
    "\n",
    "\n",
    "model.fit(train, epochs=1, validation_data=val)\n"
   ]
  }
 ],
 "metadata": {
  "kernelspec": {
   "display_name": "Python 3",
   "language": "python",
   "name": "python3"
  },
  "language_info": {
   "codemirror_mode": {
    "name": "ipython",
    "version": 3
   },
   "file_extension": ".py",
   "mimetype": "text/x-python",
   "name": "python",
   "nbconvert_exporter": "python",
   "pygments_lexer": "ipython3",
   "version": "3.10.10"
  }
 },
 "nbformat": 4,
 "nbformat_minor": 2
}
